from datetime import datetime, timedelta
from typing import Optional
from jose import JWTError, jwt
from passlib.context import CryptContext
from fastapi import Depends, HTTPException, status
from fastapi.security import OAuth2PasswordBearer
from . import schemas, models, database
from sqlalchemy.orm import Session

SECRET_KEY = "sua_chave_secreta" 
ALGORITHM = "HS256"
ACCESS_TOKEN_EXPIRE_MINUTES = 30

pwd_context = CryptContext(schemes=["bcrypt"], deprecated="auto")

oauth2_scheme = OAuth2PasswordBearer(tokenUrl="auth/login")

def verify_password(plain_password: str, hashed_password: str):
    return pwd_context.verify(plain_password, hashed_password)

def get_password_hash(password: str):
    return pwd_context.hash(password)

def authenticate_user(db: Session, username: str, password: str):
    user = db.query(models.User).filter(models.User.username == username).first()
    if not user or not verify_password(password, user.hashed_password):
        return False
    return user

def create_access_token(data: dict, expires_delta: Optional[timedelta] = None):
    to_encode = data.copy()
    if expires_delta:
        expire = datetime.utcnow() + expires_delta
    else:
        expire = datetime.utcnow() + timedelta(minutes=15)
    to_encode.update({"exp": expire})
    encoded_jwt = jwt.encode(to_encode, SECRET_KEY, algorithm=ALGORITHM)
    return encoded_jwt

def get_current_user(db: Session = Depends(database.get_db), token: str = Depends(oauth2_scheme)):
    credentials_exception = HTTPException(
        status_code=status.HTTP_401_UNAUTHORIZED,
        detail="Não foi possível validar as credenciais",
        headers={"WWW-Authenticate": "Bearer"},
    )
    try:
        payload = jwt.decode(token, SECRET_KEY, algorithms=[ALGORITHM])
        username: str = payload.get("sub")
        if username is None:
            raise credentials_exception
    except JWTError:
        raise credentials_exception
    user = db.query(models.User).filter(models.User.username == username).first()
    if user is None:
        raise credentials_exception
    return user